[2023-11-20 15:21:30,048: INFO: main: welcome to my custom logger:]
[2023-11-20 15:22:13,078: INFO: main: welcome to my custom logger:]
[2023-11-30 14:28:38,501: INFO: main: >>>>>>>>>>>> Data Ingestion Stage started <<<<<<<<<<<<<<<<<:]
[2023-11-30 14:28:38,508: INFO: common: yaml file: config\config.yaml loaded successfully:]
[2023-11-30 14:28:38,519: INFO: common: yaml file: params.yaml loaded successfully:]
[2023-11-30 14:28:38,519: ERROR: main: yaml file is empty:]
Traceback (most recent call last):
  File "d:\chicken-disease_endtoend_project\src\cnnClassifier\utils\common.py", line 32, in read_yaml
    return ConfigBox(content)
  File "box\box.py", line 247, in box.box.Box.__init__
box.exceptions.BoxValueError: Cannot extrapolate Box from string

During handling of the above exception, another exception occurred:

Traceback (most recent call last):
  File "main.py", line 10, in <module>
    data_ingestion.main()
  File "d:\chicken-disease_endtoend_project\src\cnnClassifier\pipeline\stage_01_data_ingestion.py", line 14, in main
    config = ConfigurationManager()
  File "d:\chicken-disease_endtoend_project\src\cnnClassifier\config\configuration.py", line 13, in __init__
    self.params = read_yaml(params_filepath)
  File "C:\Users\user\AppData\Local\Programs\Python\Python38\lib\site-packages\ensure\main.py", line 849, in __call__
    return_val = self.f(*args, **kwargs)
  File "d:\chicken-disease_endtoend_project\src\cnnClassifier\utils\common.py", line 34, in read_yaml
    raise ValueError("yaml file is empty")
ValueError: yaml file is empty
[2023-11-30 14:30:24,192: INFO: main: >>>>>>>>>>>> Data Ingestion Stage started <<<<<<<<<<<<<<<<<:]
[2023-11-30 14:30:24,194: INFO: common: yaml file: config\config.yaml loaded successfully:]
[2023-11-30 14:30:24,200: INFO: common: yaml file: params.yaml loaded successfully:]
[2023-11-30 14:30:24,200: ERROR: main: "'ConfigBox' object has no attribute 'artifacts_root'":]
Traceback (most recent call last):
  File "box\box.py", line 503, in box.box.Box.__getitem__
KeyError: 'artifacts_root'

The above exception was the direct cause of the following exception:

Traceback (most recent call last):
  File "box\box.py", line 536, in box.box.Box.__getattr__
  File "box\box.py", line 524, in box.box.Box.__getitem__
box.exceptions.BoxKeyError: "'artifacts_root'"

During handling of the above exception, another exception occurred:

Traceback (most recent call last):
  File "box\box.py", line 538, in box.box.Box.__getattr__
AttributeError: 'ConfigBox' object has no attribute 'artifacts_root'

The above exception was the direct cause of the following exception:

Traceback (most recent call last):
  File "box\config_box.py", line 28, in box.config_box.ConfigBox.__getattr__
  File "box\box.py", line 552, in box.box.Box.__getattr__
box.exceptions.BoxKeyError: "'ConfigBox' object has no attribute 'artifacts_root'"

During handling of the above exception, another exception occurred:

Traceback (most recent call last):
  File "box\box.py", line 503, in box.box.Box.__getitem__
KeyError: 'artifacts_root'

The above exception was the direct cause of the following exception:

Traceback (most recent call last):
  File "box\box.py", line 536, in box.box.Box.__getattr__
  File "box\box.py", line 524, in box.box.Box.__getitem__
box.exceptions.BoxKeyError: "'artifacts_root'"

During handling of the above exception, another exception occurred:

Traceback (most recent call last):
  File "box\box.py", line 538, in box.box.Box.__getattr__
AttributeError: 'ConfigBox' object has no attribute 'artifacts_root'

The above exception was the direct cause of the following exception:

Traceback (most recent call last):
  File "main.py", line 10, in <module>
    data_ingestion.main()
  File "d:\chicken-disease_endtoend_project\src\cnnClassifier\pipeline\stage_01_data_ingestion.py", line 14, in main
    config = ConfigurationManager()
  File "d:\chicken-disease_endtoend_project\src\cnnClassifier\config\configuration.py", line 15, in __init__
    create_directories([self.config.artifacts_root])
  File "box\config_box.py", line 30, in box.config_box.ConfigBox.__getattr__
  File "box\box.py", line 552, in box.box.Box.__getattr__
box.exceptions.BoxKeyError: "'ConfigBox' object has no attribute 'artifacts_root'"
[2023-11-30 14:35:06,366: INFO: main: >>>>>>>>>>>> Data Ingestion Stage started <<<<<<<<<<<<<<<<<:]
[2023-11-30 14:35:06,367: INFO: common: yaml file: config\config.yaml loaded successfully:]
[2023-11-30 14:35:06,368: INFO: common: yaml file: params.yaml loaded successfully:]
[2023-11-30 14:35:06,368: ERROR: main: "'ConfigBox' object has no attribute 'artifacts_root'":]
Traceback (most recent call last):
  File "box\box.py", line 503, in box.box.Box.__getitem__
KeyError: 'artifacts_root'

The above exception was the direct cause of the following exception:

Traceback (most recent call last):
  File "box\box.py", line 536, in box.box.Box.__getattr__
  File "box\box.py", line 524, in box.box.Box.__getitem__
box.exceptions.BoxKeyError: "'artifacts_root'"

During handling of the above exception, another exception occurred:

Traceback (most recent call last):
  File "box\box.py", line 538, in box.box.Box.__getattr__
AttributeError: 'ConfigBox' object has no attribute 'artifacts_root'

The above exception was the direct cause of the following exception:

Traceback (most recent call last):
  File "box\config_box.py", line 28, in box.config_box.ConfigBox.__getattr__
  File "box\box.py", line 552, in box.box.Box.__getattr__
box.exceptions.BoxKeyError: "'ConfigBox' object has no attribute 'artifacts_root'"

During handling of the above exception, another exception occurred:

Traceback (most recent call last):
  File "box\box.py", line 503, in box.box.Box.__getitem__
KeyError: 'artifacts_root'

The above exception was the direct cause of the following exception:

Traceback (most recent call last):
  File "box\box.py", line 536, in box.box.Box.__getattr__
  File "box\box.py", line 524, in box.box.Box.__getitem__
box.exceptions.BoxKeyError: "'artifacts_root'"

During handling of the above exception, another exception occurred:

Traceback (most recent call last):
  File "box\box.py", line 538, in box.box.Box.__getattr__
AttributeError: 'ConfigBox' object has no attribute 'artifacts_root'

The above exception was the direct cause of the following exception:

Traceback (most recent call last):
  File "main.py", line 10, in <module>
    data_ingestion.main()
  File "d:\chicken-disease_endtoend_project\src\cnnClassifier\pipeline\stage_01_data_ingestion.py", line 14, in main
    config = ConfigurationManager()
  File "d:\chicken-disease_endtoend_project\src\cnnClassifier\config\configuration.py", line 15, in __init__
    create_directories([self.config.artifacts_root])
  File "box\config_box.py", line 30, in box.config_box.ConfigBox.__getattr__
  File "box\box.py", line 552, in box.box.Box.__getattr__
box.exceptions.BoxKeyError: "'ConfigBox' object has no attribute 'artifacts_root'"
[2023-11-30 14:37:40,482: INFO: main: >>>>>>>>>>>> Data Ingestion Stage started <<<<<<<<<<<<<<<<<:]
[2023-11-30 14:37:40,484: INFO: common: yaml file: config\config.yaml loaded successfully:]
[2023-11-30 14:37:40,484: INFO: common: yaml file: params.yaml loaded successfully:]
[2023-11-30 14:37:40,485: ERROR: main: "'ConfigBox' object has no attribute 'artifacts_root'":]
Traceback (most recent call last):
  File "box\box.py", line 503, in box.box.Box.__getitem__
KeyError: 'artifacts_root'

The above exception was the direct cause of the following exception:

Traceback (most recent call last):
  File "box\box.py", line 536, in box.box.Box.__getattr__
  File "box\box.py", line 524, in box.box.Box.__getitem__
box.exceptions.BoxKeyError: "'artifacts_root'"

During handling of the above exception, another exception occurred:

Traceback (most recent call last):
  File "box\box.py", line 538, in box.box.Box.__getattr__
AttributeError: 'ConfigBox' object has no attribute 'artifacts_root'

The above exception was the direct cause of the following exception:

Traceback (most recent call last):
  File "box\config_box.py", line 28, in box.config_box.ConfigBox.__getattr__
  File "box\box.py", line 552, in box.box.Box.__getattr__
box.exceptions.BoxKeyError: "'ConfigBox' object has no attribute 'artifacts_root'"

During handling of the above exception, another exception occurred:

Traceback (most recent call last):
  File "box\box.py", line 503, in box.box.Box.__getitem__
KeyError: 'artifacts_root'

The above exception was the direct cause of the following exception:

Traceback (most recent call last):
  File "box\box.py", line 536, in box.box.Box.__getattr__
  File "box\box.py", line 524, in box.box.Box.__getitem__
box.exceptions.BoxKeyError: "'artifacts_root'"

During handling of the above exception, another exception occurred:

Traceback (most recent call last):
  File "box\box.py", line 538, in box.box.Box.__getattr__
AttributeError: 'ConfigBox' object has no attribute 'artifacts_root'

The above exception was the direct cause of the following exception:

Traceback (most recent call last):
  File "main.py", line 10, in <module>
    data_ingestion.main()
  File "d:\chicken-disease_endtoend_project\src\cnnClassifier\pipeline\stage_01_data_ingestion.py", line 14, in main
    config = ConfigurationManager()
  File "d:\chicken-disease_endtoend_project\src\cnnClassifier\config\configuration.py", line 15, in __init__
    create_directories([self.config.artifacts_root])
  File "box\config_box.py", line 30, in box.config_box.ConfigBox.__getattr__
  File "box\box.py", line 552, in box.box.Box.__getattr__
box.exceptions.BoxKeyError: "'ConfigBox' object has no attribute 'artifacts_root'"
[2023-11-30 14:40:05,082: INFO: main: >>>>>>>>>>>> Data Ingestion Stage started <<<<<<<<<<<<<<<<<:]
[2023-11-30 14:40:05,084: INFO: common: yaml file: config\config.yaml loaded successfully:]
[2023-11-30 14:40:05,086: INFO: common: yaml file: params.yaml loaded successfully:]
[2023-11-30 14:40:05,086: ERROR: main: "'ConfigBox' object has no attribute 'artifacts_root'":]
Traceback (most recent call last):
  File "box\box.py", line 503, in box.box.Box.__getitem__
KeyError: 'artifacts_root'

The above exception was the direct cause of the following exception:

Traceback (most recent call last):
  File "box\box.py", line 536, in box.box.Box.__getattr__
  File "box\box.py", line 524, in box.box.Box.__getitem__
box.exceptions.BoxKeyError: "'artifacts_root'"

During handling of the above exception, another exception occurred:

Traceback (most recent call last):
  File "box\box.py", line 538, in box.box.Box.__getattr__
AttributeError: 'ConfigBox' object has no attribute 'artifacts_root'

The above exception was the direct cause of the following exception:

Traceback (most recent call last):
  File "box\config_box.py", line 28, in box.config_box.ConfigBox.__getattr__
  File "box\box.py", line 552, in box.box.Box.__getattr__
box.exceptions.BoxKeyError: "'ConfigBox' object has no attribute 'artifacts_root'"

During handling of the above exception, another exception occurred:

Traceback (most recent call last):
  File "box\box.py", line 503, in box.box.Box.__getitem__
KeyError: 'artifacts_root'

The above exception was the direct cause of the following exception:

Traceback (most recent call last):
  File "box\box.py", line 536, in box.box.Box.__getattr__
  File "box\box.py", line 524, in box.box.Box.__getitem__
box.exceptions.BoxKeyError: "'artifacts_root'"

During handling of the above exception, another exception occurred:

Traceback (most recent call last):
  File "box\box.py", line 538, in box.box.Box.__getattr__
AttributeError: 'ConfigBox' object has no attribute 'artifacts_root'

The above exception was the direct cause of the following exception:

Traceback (most recent call last):
  File "main.py", line 10, in <module>
    data_ingestion.main()
  File "d:\chicken-disease_endtoend_project\src\cnnClassifier\pipeline\stage_01_data_ingestion.py", line 14, in main
    config = ConfigurationManager()
  File "d:\chicken-disease_endtoend_project\src\cnnClassifier\config\configuration.py", line 15, in __init__
    create_directories([self.config.artifacts_root])
  File "box\config_box.py", line 30, in box.config_box.ConfigBox.__getattr__
  File "box\box.py", line 552, in box.box.Box.__getattr__
box.exceptions.BoxKeyError: "'ConfigBox' object has no attribute 'artifacts_root'"
[2023-12-04 11:00:15,059: INFO: main: >>>>>>>>>>>> Data Ingestion Stage started <<<<<<<<<<<<<<<<<:]
[2023-12-04 11:00:15,078: INFO: common: yaml file: config\config.yaml loaded successfully:]
[2023-12-04 11:00:15,083: INFO: common: yaml file: params.yaml loaded successfully:]
[2023-12-04 11:00:15,083: ERROR: main: "'ConfigBox' object has no attribute 'artifacts_root'":]
Traceback (most recent call last):
  File "box\box.py", line 503, in box.box.Box.__getitem__
KeyError: 'artifacts_root'

The above exception was the direct cause of the following exception:

Traceback (most recent call last):
  File "box\box.py", line 536, in box.box.Box.__getattr__
  File "box\box.py", line 524, in box.box.Box.__getitem__
box.exceptions.BoxKeyError: "'artifacts_root'"

During handling of the above exception, another exception occurred:

Traceback (most recent call last):
  File "box\box.py", line 538, in box.box.Box.__getattr__
AttributeError: 'ConfigBox' object has no attribute 'artifacts_root'

The above exception was the direct cause of the following exception:

Traceback (most recent call last):
  File "box\config_box.py", line 28, in box.config_box.ConfigBox.__getattr__
  File "box\box.py", line 552, in box.box.Box.__getattr__
box.exceptions.BoxKeyError: "'ConfigBox' object has no attribute 'artifacts_root'"

During handling of the above exception, another exception occurred:

Traceback (most recent call last):
  File "box\box.py", line 503, in box.box.Box.__getitem__
KeyError: 'artifacts_root'

The above exception was the direct cause of the following exception:

Traceback (most recent call last):
  File "box\box.py", line 536, in box.box.Box.__getattr__
  File "box\box.py", line 524, in box.box.Box.__getitem__
box.exceptions.BoxKeyError: "'artifacts_root'"

During handling of the above exception, another exception occurred:

Traceback (most recent call last):
  File "box\box.py", line 538, in box.box.Box.__getattr__
AttributeError: 'ConfigBox' object has no attribute 'artifacts_root'

The above exception was the direct cause of the following exception:

Traceback (most recent call last):
  File "main.py", line 10, in <module>
    data_ingestion.main()
  File "d:\chicken-disease_endtoend_project\src\cnnClassifier\pipeline\stage_01_data_ingestion.py", line 14, in main
    config = ConfigurationManager()
  File "d:\chicken-disease_endtoend_project\src\cnnClassifier\config\configuration.py", line 15, in __init__
    create_directories([self.config.artifacts_root])
  File "box\config_box.py", line 30, in box.config_box.ConfigBox.__getattr__
  File "box\box.py", line 552, in box.box.Box.__getattr__
box.exceptions.BoxKeyError: "'ConfigBox' object has no attribute 'artifacts_root'"
[2023-12-04 11:00:56,731: INFO: main: >>>>>>>>>>>> Data Ingestion Stage started <<<<<<<<<<<<<<<<<:]
[2023-12-04 11:00:56,739: INFO: common: yaml file: config\config.yaml loaded successfully:]
[2023-12-04 11:00:56,746: INFO: common: yaml file: params.yaml loaded successfully:]
[2023-12-04 11:00:56,747: ERROR: main: "'ConfigBox' object has no attribute 'artifacts_root'":]
Traceback (most recent call last):
  File "box\box.py", line 503, in box.box.Box.__getitem__
KeyError: 'artifacts_root'

The above exception was the direct cause of the following exception:

Traceback (most recent call last):
  File "box\box.py", line 536, in box.box.Box.__getattr__
  File "box\box.py", line 524, in box.box.Box.__getitem__
box.exceptions.BoxKeyError: "'artifacts_root'"

During handling of the above exception, another exception occurred:

Traceback (most recent call last):
  File "box\box.py", line 538, in box.box.Box.__getattr__
AttributeError: 'ConfigBox' object has no attribute 'artifacts_root'

The above exception was the direct cause of the following exception:

Traceback (most recent call last):
  File "box\config_box.py", line 28, in box.config_box.ConfigBox.__getattr__
  File "box\box.py", line 552, in box.box.Box.__getattr__
box.exceptions.BoxKeyError: "'ConfigBox' object has no attribute 'artifacts_root'"

During handling of the above exception, another exception occurred:

Traceback (most recent call last):
  File "box\box.py", line 503, in box.box.Box.__getitem__
KeyError: 'artifacts_root'

The above exception was the direct cause of the following exception:

Traceback (most recent call last):
  File "box\box.py", line 536, in box.box.Box.__getattr__
  File "box\box.py", line 524, in box.box.Box.__getitem__
box.exceptions.BoxKeyError: "'artifacts_root'"

During handling of the above exception, another exception occurred:

Traceback (most recent call last):
  File "box\box.py", line 538, in box.box.Box.__getattr__
AttributeError: 'ConfigBox' object has no attribute 'artifacts_root'

The above exception was the direct cause of the following exception:

Traceback (most recent call last):
  File "main.py", line 10, in <module>
    data_ingestion.main()
  File "d:\chicken-disease_endtoend_project\src\cnnClassifier\pipeline\stage_01_data_ingestion.py", line 14, in main
    config = ConfigurationManager()
  File "d:\chicken-disease_endtoend_project\src\cnnClassifier\config\configuration.py", line 15, in __init__
    create_directories([self.config.artifacts_root])
  File "box\config_box.py", line 30, in box.config_box.ConfigBox.__getattr__
  File "box\box.py", line 552, in box.box.Box.__getattr__
box.exceptions.BoxKeyError: "'ConfigBox' object has no attribute 'artifacts_root'"
[2023-12-04 11:06:23,930: INFO: main: >>>>>>>>>>>> Data Ingestion Stage started <<<<<<<<<<<<<<<<<:]
[2023-12-04 11:06:23,933: INFO: common: yaml file: config\config.yaml loaded successfully:]
[2023-12-04 11:06:23,935: INFO: common: yaml file: params.yaml loaded successfully:]
[2023-12-04 11:06:23,935: ERROR: main: "'ConfigBox' object has no attribute 'artifacts_root'":]
Traceback (most recent call last):
  File "box\box.py", line 503, in box.box.Box.__getitem__
KeyError: 'artifacts_root'

The above exception was the direct cause of the following exception:

Traceback (most recent call last):
  File "box\box.py", line 536, in box.box.Box.__getattr__
  File "box\box.py", line 524, in box.box.Box.__getitem__
box.exceptions.BoxKeyError: "'artifacts_root'"

During handling of the above exception, another exception occurred:

Traceback (most recent call last):
  File "box\box.py", line 538, in box.box.Box.__getattr__
AttributeError: 'ConfigBox' object has no attribute 'artifacts_root'

The above exception was the direct cause of the following exception:

Traceback (most recent call last):
  File "box\config_box.py", line 28, in box.config_box.ConfigBox.__getattr__
  File "box\box.py", line 552, in box.box.Box.__getattr__
box.exceptions.BoxKeyError: "'ConfigBox' object has no attribute 'artifacts_root'"

During handling of the above exception, another exception occurred:

Traceback (most recent call last):
  File "box\box.py", line 503, in box.box.Box.__getitem__
KeyError: 'artifacts_root'

The above exception was the direct cause of the following exception:

Traceback (most recent call last):
  File "box\box.py", line 536, in box.box.Box.__getattr__
  File "box\box.py", line 524, in box.box.Box.__getitem__
box.exceptions.BoxKeyError: "'artifacts_root'"

During handling of the above exception, another exception occurred:

Traceback (most recent call last):
  File "box\box.py", line 538, in box.box.Box.__getattr__
AttributeError: 'ConfigBox' object has no attribute 'artifacts_root'

The above exception was the direct cause of the following exception:

Traceback (most recent call last):
  File "main.py", line 10, in <module>
    data_ingestion.main()
  File "d:\chicken-disease_endtoend_project\src\cnnClassifier\pipeline\stage_01_data_ingestion.py", line 13, in main
    config = ConfigurationManager()
  File "d:\chicken-disease_endtoend_project\src\cnnClassifier\config\configuration.py", line 18, in __init__
    create_directories([self.config.artifacts_root])
  File "box\config_box.py", line 30, in box.config_box.ConfigBox.__getattr__
  File "box\box.py", line 552, in box.box.Box.__getattr__
box.exceptions.BoxKeyError: "'ConfigBox' object has no attribute 'artifacts_root'"
[2023-12-04 11:15:27,861: INFO: main: >>>>>>>>>>>> Data Ingestion Stage started <<<<<<<<<<<<<<<<<:]
[2023-12-04 11:15:27,863: INFO: common: yaml file: config\config.yaml loaded successfully:]
[2023-12-04 11:15:27,864: INFO: common: yaml file: params.yaml loaded successfully:]
[2023-12-04 11:15:27,865: ERROR: main: "'ConfigBox' object has no attribute 'artifacts_root'":]
Traceback (most recent call last):
  File "box\\box.py", line 592, in box.box.Box.__getitem__
KeyError: 'artifacts_root'

The above exception was the direct cause of the following exception:

Traceback (most recent call last):
  File "box\\box.py", line 631, in box.box.Box.__getattr__
  File "box\\box.py", line 619, in box.box.Box.__getitem__
box.exceptions.BoxKeyError: "'artifacts_root'"

During handling of the above exception, another exception occurred:

Traceback (most recent call last):
  File "box\\box.py", line 633, in box.box.Box.__getattr__
AttributeError: 'ConfigBox' object has no attribute 'artifacts_root'

The above exception was the direct cause of the following exception:

Traceback (most recent call last):
  File "box\\config_box.py", line 29, in box.config_box.ConfigBox.__getattr__
  File "box\\box.py", line 647, in box.box.Box.__getattr__
box.exceptions.BoxKeyError: "'ConfigBox' object has no attribute 'artifacts_root'"

During handling of the above exception, another exception occurred:

Traceback (most recent call last):
  File "box\\box.py", line 592, in box.box.Box.__getitem__
KeyError: 'artifacts_root'

The above exception was the direct cause of the following exception:

Traceback (most recent call last):
  File "box\\box.py", line 631, in box.box.Box.__getattr__
  File "box\\box.py", line 619, in box.box.Box.__getitem__
box.exceptions.BoxKeyError: "'artifacts_root'"

During handling of the above exception, another exception occurred:

Traceback (most recent call last):
  File "box\\box.py", line 633, in box.box.Box.__getattr__
AttributeError: 'ConfigBox' object has no attribute 'artifacts_root'

The above exception was the direct cause of the following exception:

Traceback (most recent call last):
  File "main.py", line 10, in <module>
    data_ingestion.main()
  File "d:\chicken-disease_endtoend_project\src\cnnClassifier\pipeline\stage_01_data_ingestion.py", line 13, in main
    config = ConfigurationManager()
  File "d:\chicken-disease_endtoend_project\src\cnnClassifier\config\configuration.py", line 18, in __init__
    create_directories([self.config.artifacts_root])
  File "box\\config_box.py", line 31, in box.config_box.ConfigBox.__getattr__
  File "box\\box.py", line 647, in box.box.Box.__getattr__
box.exceptions.BoxKeyError: "'ConfigBox' object has no attribute 'artifacts_root'"
[2023-12-04 11:20:41,410: INFO: main: >>>>>>>>>>>> Data Ingestion Stage started <<<<<<<<<<<<<<<<<:]
[2023-12-04 11:20:41,411: INFO: common: yaml file: config\config.yaml loaded successfully:]
[2023-12-04 11:20:41,412: INFO: common: yaml file: params.yaml loaded successfully:]
[2023-12-04 11:20:41,412: ERROR: main: "'ConfigBox' object has no attribute 'artifacts_root'":]
Traceback (most recent call last):
  File "box\box.py", line 503, in box.box.Box.__getitem__
KeyError: 'artifacts_root'

The above exception was the direct cause of the following exception:

Traceback (most recent call last):
  File "box\box.py", line 536, in box.box.Box.__getattr__
  File "box\box.py", line 524, in box.box.Box.__getitem__
box.exceptions.BoxKeyError: "'artifacts_root'"

During handling of the above exception, another exception occurred:

Traceback (most recent call last):
  File "box\box.py", line 538, in box.box.Box.__getattr__
AttributeError: 'ConfigBox' object has no attribute 'artifacts_root'

The above exception was the direct cause of the following exception:

Traceback (most recent call last):
  File "box\config_box.py", line 28, in box.config_box.ConfigBox.__getattr__
  File "box\box.py", line 552, in box.box.Box.__getattr__
box.exceptions.BoxKeyError: "'ConfigBox' object has no attribute 'artifacts_root'"

During handling of the above exception, another exception occurred:

Traceback (most recent call last):
  File "box\box.py", line 503, in box.box.Box.__getitem__
KeyError: 'artifacts_root'

The above exception was the direct cause of the following exception:

Traceback (most recent call last):
  File "box\box.py", line 536, in box.box.Box.__getattr__
  File "box\box.py", line 524, in box.box.Box.__getitem__
box.exceptions.BoxKeyError: "'artifacts_root'"

During handling of the above exception, another exception occurred:

Traceback (most recent call last):
  File "box\box.py", line 538, in box.box.Box.__getattr__
AttributeError: 'ConfigBox' object has no attribute 'artifacts_root'

The above exception was the direct cause of the following exception:

Traceback (most recent call last):
  File "main.py", line 10, in <module>
    data_ingestion.main()
  File "d:\chicken-disease_endtoend_project\src\cnnClassifier\pipeline\stage_01_data_ingestion.py", line 13, in main
    config = ConfigurationManager()
  File "d:\chicken-disease_endtoend_project\src\cnnClassifier\config\configuration.py", line 18, in __init__
    create_directories([self.config.artifacts_root])
  File "box\config_box.py", line 30, in box.config_box.ConfigBox.__getattr__
  File "box\box.py", line 552, in box.box.Box.__getattr__
box.exceptions.BoxKeyError: "'ConfigBox' object has no attribute 'artifacts_root'"
[2023-12-04 11:36:26,173: INFO: main: >>>>>>>>>>>> Data Ingestion Stage started <<<<<<<<<<<<<<<<<:]
[2023-12-04 11:36:26,184: INFO: common: yaml file: config\config.yaml loaded successfully:]
[2023-12-04 11:36:26,185: INFO: common: yaml file: params.yaml loaded successfully:]
[2023-12-04 11:36:26,205: ERROR: main: "'ConfigBox' object has no attribute 'artifacts_root'":]
Traceback (most recent call last):
  File "box\box.py", line 503, in box.box.Box.__getitem__
KeyError: 'artifacts_root'

The above exception was the direct cause of the following exception:

Traceback (most recent call last):
  File "box\box.py", line 536, in box.box.Box.__getattr__
  File "box\box.py", line 524, in box.box.Box.__getitem__
box.exceptions.BoxKeyError: "'artifacts_root'"

During handling of the above exception, another exception occurred:

Traceback (most recent call last):
  File "box\box.py", line 538, in box.box.Box.__getattr__
AttributeError: 'ConfigBox' object has no attribute 'artifacts_root'

The above exception was the direct cause of the following exception:

Traceback (most recent call last):
  File "box\config_box.py", line 28, in box.config_box.ConfigBox.__getattr__
  File "box\box.py", line 552, in box.box.Box.__getattr__
box.exceptions.BoxKeyError: "'ConfigBox' object has no attribute 'artifacts_root'"

During handling of the above exception, another exception occurred:

Traceback (most recent call last):
  File "box\box.py", line 503, in box.box.Box.__getitem__
KeyError: 'artifacts_root'

The above exception was the direct cause of the following exception:

Traceback (most recent call last):
  File "box\box.py", line 536, in box.box.Box.__getattr__
  File "box\box.py", line 524, in box.box.Box.__getitem__
box.exceptions.BoxKeyError: "'artifacts_root'"

During handling of the above exception, another exception occurred:

Traceback (most recent call last):
  File "box\box.py", line 538, in box.box.Box.__getattr__
AttributeError: 'ConfigBox' object has no attribute 'artifacts_root'

The above exception was the direct cause of the following exception:

Traceback (most recent call last):
  File "main.py", line 10, in <module>
    data_ingestion.main()
  File "d:\chicken-disease_endtoend_project\src\cnnClassifier\pipeline\stage_01_data_ingestion.py", line 13, in main
    config = ConfigurationManager()
  File "d:\chicken-disease_endtoend_project\src\cnnClassifier\config\configuration.py", line 18, in __init__
    create_directories([self.config.artifacts_root])
  File "box\config_box.py", line 30, in box.config_box.ConfigBox.__getattr__
  File "box\box.py", line 552, in box.box.Box.__getattr__
box.exceptions.BoxKeyError: "'ConfigBox' object has no attribute 'artifacts_root'"
[2023-12-04 14:37:46,916: INFO: main: >>>>>>>>>>>> Data Ingestion Stage started <<<<<<<<<<<<<<<<<:]
[2023-12-04 14:37:46,918: INFO: common: yaml file: config\config.yaml loaded successfully:]
[2023-12-04 14:37:46,919: INFO: common: yaml file: params.yaml loaded successfully:]
[2023-12-04 14:37:46,919: ERROR: main: "'ConfigBox' object has no attribute 'artifacts_root'":]
Traceback (most recent call last):
  File "box\box.py", line 503, in box.box.Box.__getitem__
KeyError: 'artifacts_root'

The above exception was the direct cause of the following exception:

Traceback (most recent call last):
  File "box\box.py", line 536, in box.box.Box.__getattr__
  File "box\box.py", line 524, in box.box.Box.__getitem__
box.exceptions.BoxKeyError: "'artifacts_root'"

During handling of the above exception, another exception occurred:

Traceback (most recent call last):
  File "box\box.py", line 538, in box.box.Box.__getattr__
AttributeError: 'ConfigBox' object has no attribute 'artifacts_root'

The above exception was the direct cause of the following exception:

Traceback (most recent call last):
  File "box\config_box.py", line 28, in box.config_box.ConfigBox.__getattr__
  File "box\box.py", line 552, in box.box.Box.__getattr__
box.exceptions.BoxKeyError: "'ConfigBox' object has no attribute 'artifacts_root'"

During handling of the above exception, another exception occurred:

Traceback (most recent call last):
  File "box\box.py", line 503, in box.box.Box.__getitem__
KeyError: 'artifacts_root'

The above exception was the direct cause of the following exception:

Traceback (most recent call last):
  File "box\box.py", line 536, in box.box.Box.__getattr__
  File "box\box.py", line 524, in box.box.Box.__getitem__
box.exceptions.BoxKeyError: "'artifacts_root'"

During handling of the above exception, another exception occurred:

Traceback (most recent call last):
  File "box\box.py", line 538, in box.box.Box.__getattr__
AttributeError: 'ConfigBox' object has no attribute 'artifacts_root'

The above exception was the direct cause of the following exception:

Traceback (most recent call last):
  File "main.py", line 10, in <module>
    data_ingestion.main()
  File "d:\chicken-disease_endtoend_project\src\cnnClassifier\pipeline\stage_01_data_ingestion.py", line 13, in main
    config = ConfigurationManager()
  File "d:\chicken-disease_endtoend_project\src\cnnClassifier\config\configuration.py", line 18, in __init__
    create_directories([self.config.artifacts_root])
  File "box\config_box.py", line 30, in box.config_box.ConfigBox.__getattr__
  File "box\box.py", line 552, in box.box.Box.__getattr__
box.exceptions.BoxKeyError: "'ConfigBox' object has no attribute 'artifacts_root'"
