[2023-11-20 15:21:30,048: INFO: main: welcome to my custom logger:]
[2023-11-20 15:22:13,078: INFO: main: welcome to my custom logger:]
[2023-11-30 14:28:38,501: INFO: main: >>>>>>>>>>>> Data Ingestion Stage started <<<<<<<<<<<<<<<<<:]
[2023-11-30 14:28:38,508: INFO: common: yaml file: config\config.yaml loaded successfully:]
[2023-11-30 14:28:38,519: INFO: common: yaml file: params.yaml loaded successfully:]
[2023-11-30 14:28:38,519: ERROR: main: yaml file is empty:]
Traceback (most recent call last):
  File "d:\chicken-disease_endtoend_project\src\cnnClassifier\utils\common.py", line 32, in read_yaml
    return ConfigBox(content)
  File "box\box.py", line 247, in box.box.Box.__init__
box.exceptions.BoxValueError: Cannot extrapolate Box from string

During handling of the above exception, another exception occurred:

Traceback (most recent call last):
  File "main.py", line 10, in <module>
    data_ingestion.main()
  File "d:\chicken-disease_endtoend_project\src\cnnClassifier\pipeline\stage_01_data_ingestion.py", line 14, in main
    config = ConfigurationManager()
  File "d:\chicken-disease_endtoend_project\src\cnnClassifier\config\configuration.py", line 13, in __init__
    self.params = read_yaml(params_filepath)
  File "C:\Users\user\AppData\Local\Programs\Python\Python38\lib\site-packages\ensure\main.py", line 849, in __call__
    return_val = self.f(*args, **kwargs)
  File "d:\chicken-disease_endtoend_project\src\cnnClassifier\utils\common.py", line 34, in read_yaml
    raise ValueError("yaml file is empty")
ValueError: yaml file is empty
[2023-11-30 14:30:24,192: INFO: main: >>>>>>>>>>>> Data Ingestion Stage started <<<<<<<<<<<<<<<<<:]
[2023-11-30 14:30:24,194: INFO: common: yaml file: config\config.yaml loaded successfully:]
[2023-11-30 14:30:24,200: INFO: common: yaml file: params.yaml loaded successfully:]
[2023-11-30 14:30:24,200: ERROR: main: "'ConfigBox' object has no attribute 'artifacts_root'":]
Traceback (most recent call last):
  File "box\box.py", line 503, in box.box.Box.__getitem__
KeyError: 'artifacts_root'

The above exception was the direct cause of the following exception:

Traceback (most recent call last):
  File "box\box.py", line 536, in box.box.Box.__getattr__
  File "box\box.py", line 524, in box.box.Box.__getitem__
box.exceptions.BoxKeyError: "'artifacts_root'"

During handling of the above exception, another exception occurred:

Traceback (most recent call last):
  File "box\box.py", line 538, in box.box.Box.__getattr__
AttributeError: 'ConfigBox' object has no attribute 'artifacts_root'

The above exception was the direct cause of the following exception:

Traceback (most recent call last):
  File "box\config_box.py", line 28, in box.config_box.ConfigBox.__getattr__
  File "box\box.py", line 552, in box.box.Box.__getattr__
box.exceptions.BoxKeyError: "'ConfigBox' object has no attribute 'artifacts_root'"

During handling of the above exception, another exception occurred:

Traceback (most recent call last):
  File "box\box.py", line 503, in box.box.Box.__getitem__
KeyError: 'artifacts_root'

The above exception was the direct cause of the following exception:

Traceback (most recent call last):
  File "box\box.py", line 536, in box.box.Box.__getattr__
  File "box\box.py", line 524, in box.box.Box.__getitem__
box.exceptions.BoxKeyError: "'artifacts_root'"

During handling of the above exception, another exception occurred:

Traceback (most recent call last):
  File "box\box.py", line 538, in box.box.Box.__getattr__
AttributeError: 'ConfigBox' object has no attribute 'artifacts_root'

The above exception was the direct cause of the following exception:

Traceback (most recent call last):
  File "main.py", line 10, in <module>
    data_ingestion.main()
  File "d:\chicken-disease_endtoend_project\src\cnnClassifier\pipeline\stage_01_data_ingestion.py", line 14, in main
    config = ConfigurationManager()
  File "d:\chicken-disease_endtoend_project\src\cnnClassifier\config\configuration.py", line 15, in __init__
    create_directories([self.config.artifacts_root])
  File "box\config_box.py", line 30, in box.config_box.ConfigBox.__getattr__
  File "box\box.py", line 552, in box.box.Box.__getattr__
box.exceptions.BoxKeyError: "'ConfigBox' object has no attribute 'artifacts_root'"
[2023-11-30 14:35:06,366: INFO: main: >>>>>>>>>>>> Data Ingestion Stage started <<<<<<<<<<<<<<<<<:]
[2023-11-30 14:35:06,367: INFO: common: yaml file: config\config.yaml loaded successfully:]
[2023-11-30 14:35:06,368: INFO: common: yaml file: params.yaml loaded successfully:]
[2023-11-30 14:35:06,368: ERROR: main: "'ConfigBox' object has no attribute 'artifacts_root'":]
Traceback (most recent call last):
  File "box\box.py", line 503, in box.box.Box.__getitem__
KeyError: 'artifacts_root'

The above exception was the direct cause of the following exception:

Traceback (most recent call last):
  File "box\box.py", line 536, in box.box.Box.__getattr__
  File "box\box.py", line 524, in box.box.Box.__getitem__
box.exceptions.BoxKeyError: "'artifacts_root'"

During handling of the above exception, another exception occurred:

Traceback (most recent call last):
  File "box\box.py", line 538, in box.box.Box.__getattr__
AttributeError: 'ConfigBox' object has no attribute 'artifacts_root'

The above exception was the direct cause of the following exception:

Traceback (most recent call last):
  File "box\config_box.py", line 28, in box.config_box.ConfigBox.__getattr__
  File "box\box.py", line 552, in box.box.Box.__getattr__
box.exceptions.BoxKeyError: "'ConfigBox' object has no attribute 'artifacts_root'"

During handling of the above exception, another exception occurred:

Traceback (most recent call last):
  File "box\box.py", line 503, in box.box.Box.__getitem__
KeyError: 'artifacts_root'

The above exception was the direct cause of the following exception:

Traceback (most recent call last):
  File "box\box.py", line 536, in box.box.Box.__getattr__
  File "box\box.py", line 524, in box.box.Box.__getitem__
box.exceptions.BoxKeyError: "'artifacts_root'"

During handling of the above exception, another exception occurred:

Traceback (most recent call last):
  File "box\box.py", line 538, in box.box.Box.__getattr__
AttributeError: 'ConfigBox' object has no attribute 'artifacts_root'

The above exception was the direct cause of the following exception:

Traceback (most recent call last):
  File "main.py", line 10, in <module>
    data_ingestion.main()
  File "d:\chicken-disease_endtoend_project\src\cnnClassifier\pipeline\stage_01_data_ingestion.py", line 14, in main
    config = ConfigurationManager()
  File "d:\chicken-disease_endtoend_project\src\cnnClassifier\config\configuration.py", line 15, in __init__
    create_directories([self.config.artifacts_root])
  File "box\config_box.py", line 30, in box.config_box.ConfigBox.__getattr__
  File "box\box.py", line 552, in box.box.Box.__getattr__
box.exceptions.BoxKeyError: "'ConfigBox' object has no attribute 'artifacts_root'"
[2023-11-30 14:37:40,482: INFO: main: >>>>>>>>>>>> Data Ingestion Stage started <<<<<<<<<<<<<<<<<:]
[2023-11-30 14:37:40,484: INFO: common: yaml file: config\config.yaml loaded successfully:]
[2023-11-30 14:37:40,484: INFO: common: yaml file: params.yaml loaded successfully:]
[2023-11-30 14:37:40,485: ERROR: main: "'ConfigBox' object has no attribute 'artifacts_root'":]
Traceback (most recent call last):
  File "box\box.py", line 503, in box.box.Box.__getitem__
KeyError: 'artifacts_root'

The above exception was the direct cause of the following exception:

Traceback (most recent call last):
  File "box\box.py", line 536, in box.box.Box.__getattr__
  File "box\box.py", line 524, in box.box.Box.__getitem__
box.exceptions.BoxKeyError: "'artifacts_root'"

During handling of the above exception, another exception occurred:

Traceback (most recent call last):
  File "box\box.py", line 538, in box.box.Box.__getattr__
AttributeError: 'ConfigBox' object has no attribute 'artifacts_root'

The above exception was the direct cause of the following exception:

Traceback (most recent call last):
  File "box\config_box.py", line 28, in box.config_box.ConfigBox.__getattr__
  File "box\box.py", line 552, in box.box.Box.__getattr__
box.exceptions.BoxKeyError: "'ConfigBox' object has no attribute 'artifacts_root'"

During handling of the above exception, another exception occurred:

Traceback (most recent call last):
  File "box\box.py", line 503, in box.box.Box.__getitem__
KeyError: 'artifacts_root'

The above exception was the direct cause of the following exception:

Traceback (most recent call last):
  File "box\box.py", line 536, in box.box.Box.__getattr__
  File "box\box.py", line 524, in box.box.Box.__getitem__
box.exceptions.BoxKeyError: "'artifacts_root'"

During handling of the above exception, another exception occurred:

Traceback (most recent call last):
  File "box\box.py", line 538, in box.box.Box.__getattr__
AttributeError: 'ConfigBox' object has no attribute 'artifacts_root'

The above exception was the direct cause of the following exception:

Traceback (most recent call last):
  File "main.py", line 10, in <module>
    data_ingestion.main()
  File "d:\chicken-disease_endtoend_project\src\cnnClassifier\pipeline\stage_01_data_ingestion.py", line 14, in main
    config = ConfigurationManager()
  File "d:\chicken-disease_endtoend_project\src\cnnClassifier\config\configuration.py", line 15, in __init__
    create_directories([self.config.artifacts_root])
  File "box\config_box.py", line 30, in box.config_box.ConfigBox.__getattr__
  File "box\box.py", line 552, in box.box.Box.__getattr__
box.exceptions.BoxKeyError: "'ConfigBox' object has no attribute 'artifacts_root'"
[2023-11-30 14:40:05,082: INFO: main: >>>>>>>>>>>> Data Ingestion Stage started <<<<<<<<<<<<<<<<<:]
[2023-11-30 14:40:05,084: INFO: common: yaml file: config\config.yaml loaded successfully:]
[2023-11-30 14:40:05,086: INFO: common: yaml file: params.yaml loaded successfully:]
[2023-11-30 14:40:05,086: ERROR: main: "'ConfigBox' object has no attribute 'artifacts_root'":]
Traceback (most recent call last):
  File "box\box.py", line 503, in box.box.Box.__getitem__
KeyError: 'artifacts_root'

The above exception was the direct cause of the following exception:

Traceback (most recent call last):
  File "box\box.py", line 536, in box.box.Box.__getattr__
  File "box\box.py", line 524, in box.box.Box.__getitem__
box.exceptions.BoxKeyError: "'artifacts_root'"

During handling of the above exception, another exception occurred:

Traceback (most recent call last):
  File "box\box.py", line 538, in box.box.Box.__getattr__
AttributeError: 'ConfigBox' object has no attribute 'artifacts_root'

The above exception was the direct cause of the following exception:

Traceback (most recent call last):
  File "box\config_box.py", line 28, in box.config_box.ConfigBox.__getattr__
  File "box\box.py", line 552, in box.box.Box.__getattr__
box.exceptions.BoxKeyError: "'ConfigBox' object has no attribute 'artifacts_root'"

During handling of the above exception, another exception occurred:

Traceback (most recent call last):
  File "box\box.py", line 503, in box.box.Box.__getitem__
KeyError: 'artifacts_root'

The above exception was the direct cause of the following exception:

Traceback (most recent call last):
  File "box\box.py", line 536, in box.box.Box.__getattr__
  File "box\box.py", line 524, in box.box.Box.__getitem__
box.exceptions.BoxKeyError: "'artifacts_root'"

During handling of the above exception, another exception occurred:

Traceback (most recent call last):
  File "box\box.py", line 538, in box.box.Box.__getattr__
AttributeError: 'ConfigBox' object has no attribute 'artifacts_root'

The above exception was the direct cause of the following exception:

Traceback (most recent call last):
  File "main.py", line 10, in <module>
    data_ingestion.main()
  File "d:\chicken-disease_endtoend_project\src\cnnClassifier\pipeline\stage_01_data_ingestion.py", line 14, in main
    config = ConfigurationManager()
  File "d:\chicken-disease_endtoend_project\src\cnnClassifier\config\configuration.py", line 15, in __init__
    create_directories([self.config.artifacts_root])
  File "box\config_box.py", line 30, in box.config_box.ConfigBox.__getattr__
  File "box\box.py", line 552, in box.box.Box.__getattr__
box.exceptions.BoxKeyError: "'ConfigBox' object has no attribute 'artifacts_root'"
[2023-12-04 11:00:15,059: INFO: main: >>>>>>>>>>>> Data Ingestion Stage started <<<<<<<<<<<<<<<<<:]
[2023-12-04 11:00:15,078: INFO: common: yaml file: config\config.yaml loaded successfully:]
[2023-12-04 11:00:15,083: INFO: common: yaml file: params.yaml loaded successfully:]
[2023-12-04 11:00:15,083: ERROR: main: "'ConfigBox' object has no attribute 'artifacts_root'":]
Traceback (most recent call last):
  File "box\box.py", line 503, in box.box.Box.__getitem__
KeyError: 'artifacts_root'

The above exception was the direct cause of the following exception:

Traceback (most recent call last):
  File "box\box.py", line 536, in box.box.Box.__getattr__
  File "box\box.py", line 524, in box.box.Box.__getitem__
box.exceptions.BoxKeyError: "'artifacts_root'"

During handling of the above exception, another exception occurred:

Traceback (most recent call last):
  File "box\box.py", line 538, in box.box.Box.__getattr__
AttributeError: 'ConfigBox' object has no attribute 'artifacts_root'

The above exception was the direct cause of the following exception:

Traceback (most recent call last):
  File "box\config_box.py", line 28, in box.config_box.ConfigBox.__getattr__
  File "box\box.py", line 552, in box.box.Box.__getattr__
box.exceptions.BoxKeyError: "'ConfigBox' object has no attribute 'artifacts_root'"

During handling of the above exception, another exception occurred:

Traceback (most recent call last):
  File "box\box.py", line 503, in box.box.Box.__getitem__
KeyError: 'artifacts_root'

The above exception was the direct cause of the following exception:

Traceback (most recent call last):
  File "box\box.py", line 536, in box.box.Box.__getattr__
  File "box\box.py", line 524, in box.box.Box.__getitem__
box.exceptions.BoxKeyError: "'artifacts_root'"

During handling of the above exception, another exception occurred:

Traceback (most recent call last):
  File "box\box.py", line 538, in box.box.Box.__getattr__
AttributeError: 'ConfigBox' object has no attribute 'artifacts_root'

The above exception was the direct cause of the following exception:

Traceback (most recent call last):
  File "main.py", line 10, in <module>
    data_ingestion.main()
  File "d:\chicken-disease_endtoend_project\src\cnnClassifier\pipeline\stage_01_data_ingestion.py", line 14, in main
    config = ConfigurationManager()
  File "d:\chicken-disease_endtoend_project\src\cnnClassifier\config\configuration.py", line 15, in __init__
    create_directories([self.config.artifacts_root])
  File "box\config_box.py", line 30, in box.config_box.ConfigBox.__getattr__
  File "box\box.py", line 552, in box.box.Box.__getattr__
box.exceptions.BoxKeyError: "'ConfigBox' object has no attribute 'artifacts_root'"
[2023-12-04 11:00:56,731: INFO: main: >>>>>>>>>>>> Data Ingestion Stage started <<<<<<<<<<<<<<<<<:]
[2023-12-04 11:00:56,739: INFO: common: yaml file: config\config.yaml loaded successfully:]
[2023-12-04 11:00:56,746: INFO: common: yaml file: params.yaml loaded successfully:]
[2023-12-04 11:00:56,747: ERROR: main: "'ConfigBox' object has no attribute 'artifacts_root'":]
Traceback (most recent call last):
  File "box\box.py", line 503, in box.box.Box.__getitem__
KeyError: 'artifacts_root'

The above exception was the direct cause of the following exception:

Traceback (most recent call last):
  File "box\box.py", line 536, in box.box.Box.__getattr__
  File "box\box.py", line 524, in box.box.Box.__getitem__
box.exceptions.BoxKeyError: "'artifacts_root'"

During handling of the above exception, another exception occurred:

Traceback (most recent call last):
  File "box\box.py", line 538, in box.box.Box.__getattr__
AttributeError: 'ConfigBox' object has no attribute 'artifacts_root'

The above exception was the direct cause of the following exception:

Traceback (most recent call last):
  File "box\config_box.py", line 28, in box.config_box.ConfigBox.__getattr__
  File "box\box.py", line 552, in box.box.Box.__getattr__
box.exceptions.BoxKeyError: "'ConfigBox' object has no attribute 'artifacts_root'"

During handling of the above exception, another exception occurred:

Traceback (most recent call last):
  File "box\box.py", line 503, in box.box.Box.__getitem__
KeyError: 'artifacts_root'

The above exception was the direct cause of the following exception:

Traceback (most recent call last):
  File "box\box.py", line 536, in box.box.Box.__getattr__
  File "box\box.py", line 524, in box.box.Box.__getitem__
box.exceptions.BoxKeyError: "'artifacts_root'"

During handling of the above exception, another exception occurred:

Traceback (most recent call last):
  File "box\box.py", line 538, in box.box.Box.__getattr__
AttributeError: 'ConfigBox' object has no attribute 'artifacts_root'

The above exception was the direct cause of the following exception:

Traceback (most recent call last):
  File "main.py", line 10, in <module>
    data_ingestion.main()
  File "d:\chicken-disease_endtoend_project\src\cnnClassifier\pipeline\stage_01_data_ingestion.py", line 14, in main
    config = ConfigurationManager()
  File "d:\chicken-disease_endtoend_project\src\cnnClassifier\config\configuration.py", line 15, in __init__
    create_directories([self.config.artifacts_root])
  File "box\config_box.py", line 30, in box.config_box.ConfigBox.__getattr__
  File "box\box.py", line 552, in box.box.Box.__getattr__
box.exceptions.BoxKeyError: "'ConfigBox' object has no attribute 'artifacts_root'"
[2023-12-04 11:06:23,930: INFO: main: >>>>>>>>>>>> Data Ingestion Stage started <<<<<<<<<<<<<<<<<:]
[2023-12-04 11:06:23,933: INFO: common: yaml file: config\config.yaml loaded successfully:]
[2023-12-04 11:06:23,935: INFO: common: yaml file: params.yaml loaded successfully:]
[2023-12-04 11:06:23,935: ERROR: main: "'ConfigBox' object has no attribute 'artifacts_root'":]
Traceback (most recent call last):
  File "box\box.py", line 503, in box.box.Box.__getitem__
KeyError: 'artifacts_root'

The above exception was the direct cause of the following exception:

Traceback (most recent call last):
  File "box\box.py", line 536, in box.box.Box.__getattr__
  File "box\box.py", line 524, in box.box.Box.__getitem__
box.exceptions.BoxKeyError: "'artifacts_root'"

During handling of the above exception, another exception occurred:

Traceback (most recent call last):
  File "box\box.py", line 538, in box.box.Box.__getattr__
AttributeError: 'ConfigBox' object has no attribute 'artifacts_root'

The above exception was the direct cause of the following exception:

Traceback (most recent call last):
  File "box\config_box.py", line 28, in box.config_box.ConfigBox.__getattr__
  File "box\box.py", line 552, in box.box.Box.__getattr__
box.exceptions.BoxKeyError: "'ConfigBox' object has no attribute 'artifacts_root'"

During handling of the above exception, another exception occurred:

Traceback (most recent call last):
  File "box\box.py", line 503, in box.box.Box.__getitem__
KeyError: 'artifacts_root'

The above exception was the direct cause of the following exception:

Traceback (most recent call last):
  File "box\box.py", line 536, in box.box.Box.__getattr__
  File "box\box.py", line 524, in box.box.Box.__getitem__
box.exceptions.BoxKeyError: "'artifacts_root'"

During handling of the above exception, another exception occurred:

Traceback (most recent call last):
  File "box\box.py", line 538, in box.box.Box.__getattr__
AttributeError: 'ConfigBox' object has no attribute 'artifacts_root'

The above exception was the direct cause of the following exception:

Traceback (most recent call last):
  File "main.py", line 10, in <module>
    data_ingestion.main()
  File "d:\chicken-disease_endtoend_project\src\cnnClassifier\pipeline\stage_01_data_ingestion.py", line 13, in main
    config = ConfigurationManager()
  File "d:\chicken-disease_endtoend_project\src\cnnClassifier\config\configuration.py", line 18, in __init__
    create_directories([self.config.artifacts_root])
  File "box\config_box.py", line 30, in box.config_box.ConfigBox.__getattr__
  File "box\box.py", line 552, in box.box.Box.__getattr__
box.exceptions.BoxKeyError: "'ConfigBox' object has no attribute 'artifacts_root'"
[2023-12-04 11:15:27,861: INFO: main: >>>>>>>>>>>> Data Ingestion Stage started <<<<<<<<<<<<<<<<<:]
[2023-12-04 11:15:27,863: INFO: common: yaml file: config\config.yaml loaded successfully:]
[2023-12-04 11:15:27,864: INFO: common: yaml file: params.yaml loaded successfully:]
[2023-12-04 11:15:27,865: ERROR: main: "'ConfigBox' object has no attribute 'artifacts_root'":]
Traceback (most recent call last):
  File "box\\box.py", line 592, in box.box.Box.__getitem__
KeyError: 'artifacts_root'

The above exception was the direct cause of the following exception:

Traceback (most recent call last):
  File "box\\box.py", line 631, in box.box.Box.__getattr__
  File "box\\box.py", line 619, in box.box.Box.__getitem__
box.exceptions.BoxKeyError: "'artifacts_root'"

During handling of the above exception, another exception occurred:

Traceback (most recent call last):
  File "box\\box.py", line 633, in box.box.Box.__getattr__
AttributeError: 'ConfigBox' object has no attribute 'artifacts_root'

The above exception was the direct cause of the following exception:

Traceback (most recent call last):
  File "box\\config_box.py", line 29, in box.config_box.ConfigBox.__getattr__
  File "box\\box.py", line 647, in box.box.Box.__getattr__
box.exceptions.BoxKeyError: "'ConfigBox' object has no attribute 'artifacts_root'"

During handling of the above exception, another exception occurred:

Traceback (most recent call last):
  File "box\\box.py", line 592, in box.box.Box.__getitem__
KeyError: 'artifacts_root'

The above exception was the direct cause of the following exception:

Traceback (most recent call last):
  File "box\\box.py", line 631, in box.box.Box.__getattr__
  File "box\\box.py", line 619, in box.box.Box.__getitem__
box.exceptions.BoxKeyError: "'artifacts_root'"

During handling of the above exception, another exception occurred:

Traceback (most recent call last):
  File "box\\box.py", line 633, in box.box.Box.__getattr__
AttributeError: 'ConfigBox' object has no attribute 'artifacts_root'

The above exception was the direct cause of the following exception:

Traceback (most recent call last):
  File "main.py", line 10, in <module>
    data_ingestion.main()
  File "d:\chicken-disease_endtoend_project\src\cnnClassifier\pipeline\stage_01_data_ingestion.py", line 13, in main
    config = ConfigurationManager()
  File "d:\chicken-disease_endtoend_project\src\cnnClassifier\config\configuration.py", line 18, in __init__
    create_directories([self.config.artifacts_root])
  File "box\\config_box.py", line 31, in box.config_box.ConfigBox.__getattr__
  File "box\\box.py", line 647, in box.box.Box.__getattr__
box.exceptions.BoxKeyError: "'ConfigBox' object has no attribute 'artifacts_root'"
[2023-12-04 11:20:41,410: INFO: main: >>>>>>>>>>>> Data Ingestion Stage started <<<<<<<<<<<<<<<<<:]
[2023-12-04 11:20:41,411: INFO: common: yaml file: config\config.yaml loaded successfully:]
[2023-12-04 11:20:41,412: INFO: common: yaml file: params.yaml loaded successfully:]
[2023-12-04 11:20:41,412: ERROR: main: "'ConfigBox' object has no attribute 'artifacts_root'":]
Traceback (most recent call last):
  File "box\box.py", line 503, in box.box.Box.__getitem__
KeyError: 'artifacts_root'

The above exception was the direct cause of the following exception:

Traceback (most recent call last):
  File "box\box.py", line 536, in box.box.Box.__getattr__
  File "box\box.py", line 524, in box.box.Box.__getitem__
box.exceptions.BoxKeyError: "'artifacts_root'"

During handling of the above exception, another exception occurred:

Traceback (most recent call last):
  File "box\box.py", line 538, in box.box.Box.__getattr__
AttributeError: 'ConfigBox' object has no attribute 'artifacts_root'

The above exception was the direct cause of the following exception:

Traceback (most recent call last):
  File "box\config_box.py", line 28, in box.config_box.ConfigBox.__getattr__
  File "box\box.py", line 552, in box.box.Box.__getattr__
box.exceptions.BoxKeyError: "'ConfigBox' object has no attribute 'artifacts_root'"

During handling of the above exception, another exception occurred:

Traceback (most recent call last):
  File "box\box.py", line 503, in box.box.Box.__getitem__
KeyError: 'artifacts_root'

The above exception was the direct cause of the following exception:

Traceback (most recent call last):
  File "box\box.py", line 536, in box.box.Box.__getattr__
  File "box\box.py", line 524, in box.box.Box.__getitem__
box.exceptions.BoxKeyError: "'artifacts_root'"

During handling of the above exception, another exception occurred:

Traceback (most recent call last):
  File "box\box.py", line 538, in box.box.Box.__getattr__
AttributeError: 'ConfigBox' object has no attribute 'artifacts_root'

The above exception was the direct cause of the following exception:

Traceback (most recent call last):
  File "main.py", line 10, in <module>
    data_ingestion.main()
  File "d:\chicken-disease_endtoend_project\src\cnnClassifier\pipeline\stage_01_data_ingestion.py", line 13, in main
    config = ConfigurationManager()
  File "d:\chicken-disease_endtoend_project\src\cnnClassifier\config\configuration.py", line 18, in __init__
    create_directories([self.config.artifacts_root])
  File "box\config_box.py", line 30, in box.config_box.ConfigBox.__getattr__
  File "box\box.py", line 552, in box.box.Box.__getattr__
box.exceptions.BoxKeyError: "'ConfigBox' object has no attribute 'artifacts_root'"
[2023-12-04 11:36:26,173: INFO: main: >>>>>>>>>>>> Data Ingestion Stage started <<<<<<<<<<<<<<<<<:]
[2023-12-04 11:36:26,184: INFO: common: yaml file: config\config.yaml loaded successfully:]
[2023-12-04 11:36:26,185: INFO: common: yaml file: params.yaml loaded successfully:]
[2023-12-04 11:36:26,205: ERROR: main: "'ConfigBox' object has no attribute 'artifacts_root'":]
Traceback (most recent call last):
  File "box\box.py", line 503, in box.box.Box.__getitem__
KeyError: 'artifacts_root'

The above exception was the direct cause of the following exception:

Traceback (most recent call last):
  File "box\box.py", line 536, in box.box.Box.__getattr__
  File "box\box.py", line 524, in box.box.Box.__getitem__
box.exceptions.BoxKeyError: "'artifacts_root'"

During handling of the above exception, another exception occurred:

Traceback (most recent call last):
  File "box\box.py", line 538, in box.box.Box.__getattr__
AttributeError: 'ConfigBox' object has no attribute 'artifacts_root'

The above exception was the direct cause of the following exception:

Traceback (most recent call last):
  File "box\config_box.py", line 28, in box.config_box.ConfigBox.__getattr__
  File "box\box.py", line 552, in box.box.Box.__getattr__
box.exceptions.BoxKeyError: "'ConfigBox' object has no attribute 'artifacts_root'"

During handling of the above exception, another exception occurred:

Traceback (most recent call last):
  File "box\box.py", line 503, in box.box.Box.__getitem__
KeyError: 'artifacts_root'

The above exception was the direct cause of the following exception:

Traceback (most recent call last):
  File "box\box.py", line 536, in box.box.Box.__getattr__
  File "box\box.py", line 524, in box.box.Box.__getitem__
box.exceptions.BoxKeyError: "'artifacts_root'"

During handling of the above exception, another exception occurred:

Traceback (most recent call last):
  File "box\box.py", line 538, in box.box.Box.__getattr__
AttributeError: 'ConfigBox' object has no attribute 'artifacts_root'

The above exception was the direct cause of the following exception:

Traceback (most recent call last):
  File "main.py", line 10, in <module>
    data_ingestion.main()
  File "d:\chicken-disease_endtoend_project\src\cnnClassifier\pipeline\stage_01_data_ingestion.py", line 13, in main
    config = ConfigurationManager()
  File "d:\chicken-disease_endtoend_project\src\cnnClassifier\config\configuration.py", line 18, in __init__
    create_directories([self.config.artifacts_root])
  File "box\config_box.py", line 30, in box.config_box.ConfigBox.__getattr__
  File "box\box.py", line 552, in box.box.Box.__getattr__
box.exceptions.BoxKeyError: "'ConfigBox' object has no attribute 'artifacts_root'"
[2023-12-04 14:37:46,916: INFO: main: >>>>>>>>>>>> Data Ingestion Stage started <<<<<<<<<<<<<<<<<:]
[2023-12-04 14:37:46,918: INFO: common: yaml file: config\config.yaml loaded successfully:]
[2023-12-04 14:37:46,919: INFO: common: yaml file: params.yaml loaded successfully:]
[2023-12-04 14:37:46,919: ERROR: main: "'ConfigBox' object has no attribute 'artifacts_root'":]
Traceback (most recent call last):
  File "box\box.py", line 503, in box.box.Box.__getitem__
KeyError: 'artifacts_root'

The above exception was the direct cause of the following exception:

Traceback (most recent call last):
  File "box\box.py", line 536, in box.box.Box.__getattr__
  File "box\box.py", line 524, in box.box.Box.__getitem__
box.exceptions.BoxKeyError: "'artifacts_root'"

During handling of the above exception, another exception occurred:

Traceback (most recent call last):
  File "box\box.py", line 538, in box.box.Box.__getattr__
AttributeError: 'ConfigBox' object has no attribute 'artifacts_root'

The above exception was the direct cause of the following exception:

Traceback (most recent call last):
  File "box\config_box.py", line 28, in box.config_box.ConfigBox.__getattr__
  File "box\box.py", line 552, in box.box.Box.__getattr__
box.exceptions.BoxKeyError: "'ConfigBox' object has no attribute 'artifacts_root'"

During handling of the above exception, another exception occurred:

Traceback (most recent call last):
  File "box\box.py", line 503, in box.box.Box.__getitem__
KeyError: 'artifacts_root'

The above exception was the direct cause of the following exception:

Traceback (most recent call last):
  File "box\box.py", line 536, in box.box.Box.__getattr__
  File "box\box.py", line 524, in box.box.Box.__getitem__
box.exceptions.BoxKeyError: "'artifacts_root'"

During handling of the above exception, another exception occurred:

Traceback (most recent call last):
  File "box\box.py", line 538, in box.box.Box.__getattr__
AttributeError: 'ConfigBox' object has no attribute 'artifacts_root'

The above exception was the direct cause of the following exception:

Traceback (most recent call last):
  File "main.py", line 10, in <module>
    data_ingestion.main()
  File "d:\chicken-disease_endtoend_project\src\cnnClassifier\pipeline\stage_01_data_ingestion.py", line 13, in main
    config = ConfigurationManager()
  File "d:\chicken-disease_endtoend_project\src\cnnClassifier\config\configuration.py", line 18, in __init__
    create_directories([self.config.artifacts_root])
  File "box\config_box.py", line 30, in box.config_box.ConfigBox.__getattr__
  File "box\box.py", line 552, in box.box.Box.__getattr__
box.exceptions.BoxKeyError: "'ConfigBox' object has no attribute 'artifacts_root'"
[2023-12-12 15:32:23,896: INFO: main: >>>>>>>>>>>> Data Ingestion Stage started <<<<<<<<<<<<<<<<<:]
[2023-12-12 15:32:23,900: INFO: common: yaml file: config\config.yaml loaded successfully:]
[2023-12-12 15:32:23,904: INFO: common: yaml file: params.yaml loaded successfully:]
[2023-12-12 15:32:23,905: INFO: common: directory: artifacts created successfully:]
[2023-12-12 15:32:23,906: INFO: common: directory: artifacts/data_ingestion created successfully:]
[2023-12-12 15:32:24,973: INFO: data_ingestion: artifacts/data_ingestion/data.zip download! with following info: 
Connection: close
Content-Length: 11616915
Cache-Control: max-age=300
Content-Security-Policy: default-src 'none'; style-src 'unsafe-inline'; sandbox
Content-Type: application/zip
ETag: "adf745abc03891fe493c3be264ec012691fe3fa21d861f35a27edbe6d86a76b1"
Strict-Transport-Security: max-age=31536000
X-Content-Type-Options: nosniff
X-Frame-Options: deny
X-XSS-Protection: 1; mode=block
X-GitHub-Request-Id: C1AC:5C2B:356B78:41562C:6578B580
Accept-Ranges: bytes
Date: Tue, 12 Dec 2023 20:32:23 GMT
Via: 1.1 varnish
X-Served-By: cache-chi-klot8100022-CHI
X-Cache: HIT
X-Cache-Hits: 0
X-Timer: S1702413144.642622,VS0,VE81
Vary: Authorization,Accept-Encoding,Origin
Access-Control-Allow-Origin: *
Cross-Origin-Resource-Policy: cross-origin
X-Fastly-Request-ID: bc3193f89a1f415f49eb46533d94a28e38151d9c
Expires: Tue, 12 Dec 2023 20:37:23 GMT
Source-Age: 0

:]
[2023-12-12 15:32:25,465: INFO: main: >>>>>>>>>>>> Data Ingestion Stage completed <<<<<<<<<<<<<<<<<

 x========================x:]
[2023-12-12 17:28:11,677: INFO: main: >>>>>>>>>>>> Data Ingestion Stage started <<<<<<<<<<<<<<<<<:]
[2023-12-12 17:28:11,748: INFO: common: yaml file: config\config.yaml loaded successfully:]
[2023-12-12 17:28:11,813: INFO: common: yaml file: params.yaml loaded successfully:]
[2023-12-12 17:28:11,813: INFO: common: directory: artifacts created successfully:]
[2023-12-12 17:28:11,814: INFO: common: directory: artifacts/data_ingestion created successfully:]
[2023-12-12 17:28:11,814: INFO: data_ingestion: File already exists of size: ~ 11345 KB:]
[2023-12-12 17:28:12,609: INFO: main: >>>>>>>>>>>> Data Ingestion Stage completed <<<<<<<<<<<<<<<<<

 x========================x:]
[2023-12-12 18:12:22,930: INFO: common: yaml file: config\config.yaml loaded successfully:]
[2023-12-12 18:12:22,940: INFO: common: yaml file: params.yaml loaded successfully:]
[2023-12-12 18:12:22,941: INFO: common: directory: artifacts created successfully:]
[2023-12-12 18:12:22,943: INFO: common: directory: artifacts/prepare_base_model created successfully:]
[2023-12-12 18:13:22,048: INFO: common: yaml file: config\config.yaml loaded successfully:]
[2023-12-12 18:13:22,051: INFO: common: yaml file: params.yaml loaded successfully:]
[2023-12-12 18:13:22,052: INFO: common: directory: artifacts created successfully:]
[2023-12-12 18:13:22,054: INFO: common: directory: artifacts/prepare_base_model created successfully:]
[2023-12-12 18:14:19,154: INFO: common: yaml file: config\config.yaml loaded successfully:]
[2023-12-12 18:14:19,160: INFO: common: yaml file: params.yaml loaded successfully:]
[2023-12-12 18:14:19,190: INFO: common: directory: artifacts created successfully:]
[2023-12-12 18:14:19,192: INFO: common: directory: artifacts/prepare_base_model created successfully:]
[2023-12-12 18:15:45,391: INFO: common: yaml file: config\config.yaml loaded successfully:]
[2023-12-12 18:15:45,395: INFO: common: yaml file: params.yaml loaded successfully:]
[2023-12-12 18:15:45,396: INFO: common: directory: artifacts created successfully:]
[2023-12-12 18:15:45,399: INFO: common: directory: artifacts/prepare_base_model created successfully:]
[2023-12-12 18:16:04,002: WARNING: saving_utils: Compiled the loaded model, but the compiled metrics have yet to be built. `model.compile_metrics` will be empty until you train or evaluate the model.:]
[2023-12-12 18:32:57,526: INFO: main: >>>>>>>>>>>> Data Ingestion Stage started <<<<<<<<<<<<<<<<<:]
[2023-12-12 18:32:57,530: INFO: common: yaml file: config\config.yaml loaded successfully:]
[2023-12-12 18:32:57,532: INFO: common: yaml file: params.yaml loaded successfully:]
[2023-12-12 18:32:57,533: INFO: common: directory: artifacts created successfully:]
[2023-12-12 18:32:57,533: INFO: common: directory: artifacts/data_ingestion created successfully:]
[2023-12-12 18:32:57,534: INFO: data_ingestion: File already exists of size: ~ 11345 KB:]
[2023-12-12 18:32:57,934: INFO: main: >>>>>>>>>>>> Data Ingestion Stage completed <<<<<<<<<<<<<<<<<

 x========================x:]
[2023-12-12 18:32:57,935: INFO: main: *******************:]
[2023-12-12 18:32:57,936: INFO: main: >>>>>> stage Prepare base model started <<<<<<:]
[2023-12-12 18:32:57,938: INFO: common: yaml file: config\config.yaml loaded successfully:]
[2023-12-12 18:32:57,941: INFO: common: yaml file: params.yaml loaded successfully:]
[2023-12-12 18:32:57,941: INFO: common: directory: artifacts created successfully:]
[2023-12-12 18:32:57,942: INFO: common: directory: artifacts/prepare_base_model created successfully:]
[2023-12-12 18:32:58,434: WARNING: saving_utils: Compiled the loaded model, but the compiled metrics have yet to be built. `model.compile_metrics` will be empty until you train or evaluate the model.:]
[2023-12-12 18:32:59,915: INFO: main: >>>>>> stage Prepare base model completed <<<<<<

x==========x:]
[2023-12-13 13:07:00,810: INFO: common: yaml file: config\config.yaml loaded successfully:]
[2023-12-13 13:07:00,813: INFO: common: yaml file: params.yaml loaded successfully:]
[2023-12-13 13:07:00,815: INFO: common: directory: artifacts created successfully:]
[2023-12-13 13:07:00,817: INFO: common: directory: artifacts\prepare_callbacks\checkpoint_dir created successfully:]
[2023-12-13 13:07:00,819: INFO: common: directory: artifacts\prepare_callbacks\base_tensorboard_log_dir created successfully:]
[2023-12-13 13:08:23,743: INFO: common: yaml file: config\config.yaml loaded successfully:]
[2023-12-13 13:08:23,746: INFO: common: yaml file: params.yaml loaded successfully:]
[2023-12-13 13:08:23,748: INFO: common: directory: artifacts created successfully:]
[2023-12-13 13:08:23,750: INFO: common: directory: artifacts\prepare_callbacks\checkpoint_dir created successfully:]
[2023-12-13 13:08:23,751: INFO: common: directory: artifacts\prepare_callbacks\base_tensorboard_log_dir created successfully:]
[2023-12-13 13:09:22,485: INFO: common: yaml file: config\config.yaml loaded successfully:]
[2023-12-13 13:09:22,489: INFO: common: yaml file: params.yaml loaded successfully:]
[2023-12-13 13:09:22,491: INFO: common: directory: artifacts created successfully:]
[2023-12-13 13:09:22,493: INFO: common: directory: artifacts\prepare_callbacks\checkpoint_dir created successfully:]
[2023-12-13 13:09:22,494: INFO: common: directory: artifacts\prepare_callbacks\base_tensorboard_log_dir created successfully:]
[2023-12-13 13:09:33,022: INFO: common: yaml file: config\config.yaml loaded successfully:]
[2023-12-13 13:09:33,026: INFO: common: yaml file: params.yaml loaded successfully:]
[2023-12-13 13:09:33,027: INFO: common: directory: artifacts created successfully:]
[2023-12-13 13:09:33,052: INFO: common: directory: artifacts\prepare_callbacks\checkpoint_dir created successfully:]
[2023-12-13 13:09:33,054: INFO: common: directory: artifacts\prepare_callbacks\base_tensorboard_log_dir created successfully:]
[2023-12-13 13:11:04,826: INFO: common: yaml file: config\config.yaml loaded successfully:]
[2023-12-13 13:11:04,831: INFO: common: yaml file: params.yaml loaded successfully:]
[2023-12-13 13:11:04,833: INFO: common: directory: artifacts created successfully:]
[2023-12-13 13:11:04,837: INFO: common: directory: artifacts\prepare_callbacks\checkpoint_dir created successfully:]
[2023-12-13 13:11:04,840: INFO: common: directory: artifacts\prepare_callbacks\tensorboard_log_dir created successfully:]
